(dp1
S'output'
p2
S'<type \'exceptions.RuntimeError\'> Failure to connect, tried 5 times:\nTraceback (most recent call last):\n  File "C:\\Users\\ferna\\Downloads\\web2py\\gluon\\packages\\dal\\pydal\\base.py", line 455, in __init__\n    self._adapter = adapter(**kwargs)\n  File "C:\\Users\\ferna\\Downloads\\web2py\\gluon\\packages\\dal\\pydal\\adapters\\__init__.py", line 40, in __call__\n    obj = super(AdapterMeta, cls).__call__(*args, **kwargs)\n  File "C:\\Users\\ferna\\Downloads\\web2py\\gluon\\packages\\dal\\pydal\\adapters\\base.py", line 368, in __init__\n    super(SQLAdapter, self).__init__(*args, **kwargs)\n  File "C:\\Users\\ferna\\Downloads\\web2py\\gluon\\packages\\dal\\pydal\\adapters\\base.py", line 52, in __init__\n    self.reconnect()\n  File "C:\\Users\\ferna\\Downloads\\web2py\\gluon\\packages\\dal\\pydal\\connection.py", line 152, in reconnect\n    self.connection = self.connector()\n  File "C:\\Users\\ferna\\Downloads\\web2py\\gluon\\packages\\dal\\pydal\\adapters\\mysql.py", line 52, in connector\n    return self.driver.connect(**self.driver_args)\n  File "MySQLdb/__init__.py", line 81, in Connect\n  File "MySQLdb/connections.py", line 193, in __init__\nOperationalError: (1049, "Unknown database \'avalweb\'")\n'
p3
sS'layer'
p4
S'C:\\Users\\ferna\\Downloads\\web2py\\applications\\avalweb3\\models\\db.py'
p5
sS'code'
p6
S'<code object <module> at 04A0C968, file "C:\\Users\\ferna\\Downloads\\web2py\\applications\\avalweb3\\models\\db.py", line 1>'
p7
sS'snapshot'
p8
(dp9
sS'traceback'
p10
S'Traceback (most recent call last):\n  File "C:\\Users\\ferna\\Downloads\\web2py\\gluon\\restricted.py", line 219, in restricted\n    exec(ccode, environment)\n  File "C:\\Users\\ferna\\Downloads\\web2py\\applications\\avalweb3\\models\\db.py", line 1, in <module>\n    db=DAL(\'mysql://root:root@localhost/avalweb\');\n  File "C:\\Users\\ferna\\Downloads\\web2py\\gluon\\packages\\dal\\pydal\\base.py", line 170, in __call__\n    obj = super(MetaDAL, cls).__call__(*args, **kwargs)\n  File "C:\\Users\\ferna\\Downloads\\web2py\\gluon\\packages\\dal\\pydal\\base.py", line 475, in __init__\n    "Failure to connect, tried %d times:\\n%s" % (attempts, tb)\nRuntimeError: Failure to connect, tried 5 times:\nTraceback (most recent call last):\n  File "C:\\Users\\ferna\\Downloads\\web2py\\gluon\\packages\\dal\\pydal\\base.py", line 455, in __init__\n    self._adapter = adapter(**kwargs)\n  File "C:\\Users\\ferna\\Downloads\\web2py\\gluon\\packages\\dal\\pydal\\adapters\\__init__.py", line 40, in __call__\n    obj = super(AdapterMeta, cls).__call__(*args, **kwargs)\n  File "C:\\Users\\ferna\\Downloads\\web2py\\gluon\\packages\\dal\\pydal\\adapters\\base.py", line 368, in __init__\n    super(SQLAdapter, self).__init__(*args, **kwargs)\n  File "C:\\Users\\ferna\\Downloads\\web2py\\gluon\\packages\\dal\\pydal\\adapters\\base.py", line 52, in __init__\n    self.reconnect()\n  File "C:\\Users\\ferna\\Downloads\\web2py\\gluon\\packages\\dal\\pydal\\connection.py", line 152, in reconnect\n    self.connection = self.connector()\n  File "C:\\Users\\ferna\\Downloads\\web2py\\gluon\\packages\\dal\\pydal\\adapters\\mysql.py", line 52, in connector\n    return self.driver.connect(**self.driver_args)\n  File "MySQLdb/__init__.py", line 81, in Connect\n  File "MySQLdb/connections.py", line 193, in __init__\nOperationalError: (1049, "Unknown database \'avalweb\'")\n\n'
p11
s.